use crate::domain::SubscriberEmail;
use crate::email_client::EmailClient;
use crate::routes::error_chain_fmt;
use actix_web::ResponseError;
use actix_web::{HttpResponse, http::StatusCode, web};
use anyhow::Context;
use sqlx::PgPool;

#[derive(serde::Deserialize)]
pub struct BodyData {
    title: String,
    content: Content,
}

#[derive(serde::Deserialize)]
pub struct Content {
    html: String,
    text: String,
}

pub async fn publish_newsletter(
    body: web::Json<BodyData>,
    pool: web::Data<PgPool>,
    email_client: web::Data<EmailClient>,
) -> Result<HttpResponse, PublishError> {
    let subscribers = get_confirmed_subscribers(&pool).await?;

    for subscriber in subscribers {
        match subscriber {
            Ok(subscriber) => {
                email_client
                    .send_email(
                        &subscriber.email,
                        &body.title,
                        &body.content.html,
                        &body.content.text,
                    )
                    .await
                    .with_context(|| {
                        format!("Failed to send newsletter issue to {}", subscriber.email)
                    })?;
            }
            // diff bw context and with_context - with_context is lazy
            // If the context you are adding is static - e.g. context("Oh no!") - they are equivalent.
            // If the context you are adding has a runtime cost, use with_context - you avoid paying for the error
            // path when the fallible operation succeeds - Using with_context, we only invoke format! if email delivery fails.
            Err(error) => {
                tracing::warn!(
                // We record the error chain as a structured field on the log record.
                // ? is used to trigger the Debug representation of the error - to pretty-print the contents
                error.cause_chain = ?error,
                // Using `\' to split a long string literal over
                // two lines, without creating a `\n` character.
                "Skipping a confirmed subscriber. \
                Their stored contact details are invalid",
                );
            }
        }
    }

    Ok(HttpResponse::Ok().finish())
}

struct ConfirmedSubscriber {
    email: SubscriberEmail,
}

#[tracing::instrument(name = "Get confirmed subscribers", skip(pool))]
async fn get_confirmed_subscribers(
    pool: &PgPool,
    // We are returning a `Vec` of `Result`s in the happy case.
    // This allows the caller to bubble up errors due to network issues or other
    // transient failures using the `?` operator, while the compiler
    // forces them to handle the subtler mapping error.
    // See http://sled.rs/errors.html for a deep-dive about this technique.
) -> Result<Vec<Result<ConfirmedSubscriber, anyhow::Error>>, anyhow::Error> {
    // We only need `Row` to map the data coming out of this query.
    // Nesting its definition inside the function itself is a simple way
    // to clearly communicate this coupling (and to ensure it doesn't get used elsewhere by mistake).
    // not needed here - as query is simple enough
    // struct Row {
    //     email: String,
    // }

    // sqlx::query_as! maps the retrieved rows to the type specified as its first argument, ConfirmedSubscriber
    // let rows = sqlx::query_as!(
    //     Row,
    //     r#"
    //         SELECT email
    //         FROM subscriptions
    //         WHERE status = 'confirmed'
    //     "#,
    // )
    // .fetch_all(pool)
    // .await?;

    let confirmed_subscribers = sqlx::query!(
        r#"
        SELECT email
        FROM subscriptions
        WHERE status = 'confirmed'
        "#,
    )
    .fetch_all(pool)
    .await?
    .into_iter()
    .map(|r| match SubscriberEmail::parse(r.email) {
        Ok(email) => Ok(ConfirmedSubscriber { email }),
        Err(error) => Err(anyhow::anyhow!(error)),
    })
    .collect();

    Ok(confirmed_subscribers)
}

#[derive(thiserror::Error)]
pub enum PublishError {
    #[error(transparent)]
    UnexpectedError(#[from] anyhow::Error),
}

impl std::fmt::Debug for PublishError {
    fn fmt(&self, f: &mut std::fmt::Formatter<'_>) -> std::fmt::Result {
        error_chain_fmt(self, f)
    }
}

impl ResponseError for PublishError {
    fn status_code(&self) -> StatusCode {
        match self {
            PublishError::UnexpectedError(_) => StatusCode::INTERNAL_SERVER_ERROR,
        }
    }
}
